Workbook

Sheet README
A1: India Bus Terminals & Routes - working dataset (built 2026-10-02)
A2: STATUS: starter database, NOT a fully verified dataset. See Data_Quality.
A3: Verification_Status values: Verified = confirmed on an official source; Partially Verified = seen in a secondary source (news/aggregator/Wikipedia); Needs Verification = listed from general knowledge, no source retrieved.
A4: No coordinates, addresses or PIN codes are filled - none could be verified. Columns are present and validated for later import.
A5: Routes: only services actually found in cited sources are included (West Bengal and Bihar-linked). No routes were generated by pairing terminals.
A6: Lakshadweep: islands have no inter-city bus terminal records yet; cities only.
A7: Terminal_Type, Route_Type, Verification_Status and Y/N fields use dropdown validation.

Sheet Bus_Terminals
A1: Terminal_ID | B1: Terminal_Name | C1: Terminal_Type | D1: City | E1: District | F1: State | G1: Union_Territory | H1: Country | I1: Full_Address | J1: Latitude | K1: Longitude | L1: PIN_Code | M1: Major_Terminal | N1: Intercity | O1: State_Transport | P1: Operators | Q1: Alternate_Names | R1: Search_Keywords | S1: Source_URL | T1: Source_Name | U1: Verification_Status | V1: Last_Verified | W1: Notes
A2: WB-KOLKATA-ESPLANADEBUS-001 | B2: Esplanade Bus Terminus | C2: Bus Terminal | D2: Kolkata | F2: West Bengal | H2: India | M2: Y | N2: Y | O2: Y | P2: West Bengal Transport Corporation | Q2: Esplanade, Esplanade Bus Stand, Esplanade L-20 Terminus, Esplanade LDS Terminus, Dharmatala Bus Stand | R2: Kolkata, Esplanade Bus Terminus, Esplanade, Esplanade Bus Stand, Esplanade L-20 Terminus, Esplanade LDS Terminus, Dharmatala Bus Stand, Kolkata bus, Kolkata bus stand, bus terminal Kolkata, West Bengal | S2: https://housing.com/news/217-bus-route-kolkata-narayanpur-to-babughat; https://www.makemytrip.com/bus-tickets/wbtc-ctc-from-kolkata-to-bolpur-online-bus-tickets.html | T2: housing.com - 217 bus route Kolkata; MakeMyTrip - WBTC Kolkata to Bolpur | U2: Partially Verified | V2: 46297 | W2: Name/location from secondary source; official confirmation, address and coordinates pending. Multiple boarding labels seen (Esplanade Bus Stand, L-20, LDS) - treated as one site pending check; news mentions possible relocation.
A3: WB-KOLKATA-BABUGHATBUST-002 | B3: Babughat Bus Terminus | C3: Bus Terminal | D3: Kolkata | F3: West Bengal | H3: India | M3: Y | N3: Y | O3: Y | P3: West Bengal Transport Corporation | Q3: Babughat, Babughat Bus Stand | R3: Kolkata, Babughat Bus Terminus, Babughat, Babughat Bus Stand, Kolkata bus, Kolkata bus stand, bus terminal Kolkata, West Bengal | S3: https://housing.com/news/217-bus-route-kolkata-narayanpur-to-babughat; https://housing.com/news/205-bus-route-in-kolkata-bansdroni-to-babughat | T3: housing.com - 217 bus route Kolkata; housing.com - 205 bus route Kolkata | U3: Partially Verified | V3: 46297 | W3: Name/location from secondary source; official confirmation, address and coordinates pending.
A4: WB-KOLKATA-KARUNAMOYEEB-003 | B4: Karunamoyee Bus Terminus | C4: Bus Terminal | D4: Kolkata | F4: West Bengal | H4: India | M4: Y | N4: Y | O4: Unknown | Q4: Karunamoyee, Karunamoyee Bus Stand, Salt Lake Karunamoyee | R4: Kolkata, Karunamoyee Bus Terminus, Karunamoyee, Karunamoyee Bus Stand, Salt Lake Karunamoyee, Kolkata bus, Kolkata bus stand, bus terminal Kolkata, West Bengal | U4: Needs Verification | W4: Included from general knowledge of the transport network; no source retrieved yet. Name, exact location and coordinates need verification.
A5: WB-KOLKATA-SHAPOORJIBUS-004 | B5: Shapoorji Bus Terminal | C5: Bus Terminal | D5: Kolkata | F5: West Bengal | H5: India | M5: N | N5: N | O5: Y | P5: West Bengal Transport Corporation | Q5: Shapoorji | R5: Kolkata, Shapoorji Bus Terminal, Shapoorji, Kolkata bus, Kolkata bus stand, bus terminal Kolkata, West Bengal | S5: https://housing.com/news/ac-12-bus-route-kolkata-shapoorji-to-howrah/ | T5: housing.com - AC12 bus route Kolkata | U5: Partially Verified | V5: 46297 | W5: Name/location from secondary source; official confirmation, address and coordinates pending.
A6: WB-KOLKATA-NARAYANPURBU-005 | B6: Narayanpur Bus Terminal | C6: Bus Terminal | D6: Kolkata | F6: West Bengal | H6: India | M6: N | N6: N | O6: Y | P6: West Bengal Transport Corporation | Q6: Narayanpur | R6: Kolkata, Narayanpur Bus Terminal, Narayanpur, Kolkata bus, Kolkata bus stand, bus terminal Kolkata, West Bengal | S6: https://housing.com/news/217-bus-route-kolkata-narayanpur-to-babughat | T6: housing.com - 217 bus route Kolkata | U6: Partially Verified | V6: 46297 | W6: Name/location from secondary source; official confirmation, address and coordinates pending.
A7: WB-KOLKATA-BANSDRONIBUS-006 | B7: Bansdroni Bus Terminal | C7: Bus Terminal | D7: Kolkata | F7: West Bengal | H7: India | M7: N | N7: N | O7: Y | P7: West Bengal Transport Corporation | Q7: Bansdroni | R7: Kolkata, Bansdroni Bus Terminal, Bansdroni, Kolkata bus, Kolkata bus stand, bus terminal Kolkata, West Bengal | S7: https://housing.com/news/205-bus-route-in-kolkata-bansdroni-to-babughat | T7: housing.com - 205 bus route Kolkata | U7: Partially Verified | V7: 46297 | W7: Name/location from secondary source; official confirmation, address and coordinates pending.
A8: WB-KOLKATA-GARIABUSTERM-007 | B8: Garia Bus Terminus | C8: Bus Terminal | D8: Kolkata | F8: West Bengal | H8: India | M8: N | N8: N | O8: Unknown | Q8: Garia | R8: Kolkata, Garia Bus Terminus, Garia, Kolkata bus, Kolkata bus stand, bus terminal Kolkata, West Bengal | U8: Needs Verification | W8: Included from general knowledge of the transport network; no source retrieved yet. Name, exact location and coordinates need verification.
A9: WB-KOLKATA-RAJARHATBUST-008 | B9: Rajarhat Bus Terminus | C9: Bus Terminal | D9: Kolkata | F9: West Bengal | H9: India | M9: N | N9: N | O9: Unknown | Q9: Newtown, Rajarhat | R9: Kolkata, Rajarhat Bus Terminus, Newtown, Rajarhat, Kolkata bus, Kolkata bus stand, bus terminal Kolkata, West Bengal | U9: Needs Verification | W9: Included from general knowledge of the transport network; no source retrieved yet. Name, exact location and coordinates need verification.
A10: WB-KOLKATA-HOWRAHBUSSTA-009 | B10: Howrah Bus Stand | C10: Bus Terminal | D10: Kolkata | F10: West Bengal | H10: India | M10: Y | N10: Y | O10: Y | P10: West Bengal Transport Corporation | Q10: Howrah Station Bus Stand, Howrah Bus Terminus | R10: Kolkata, Howrah Bus Stand, Howrah Station Bus Stand, Howrah Bus Terminus, Kolkata bus, Kolkata bus stand, bus terminal Kolkata, West Bengal | S10: https://housing.com/news/ac-12-bus-route-kolkata-shapoorji-to-howrah/ | T10: housing.com - AC12 bus route Kolkata | U10: Partially Verified | V10: 46297 | W10: Name/location from secondary source; official confirmation, address and coordinates pending. Source lists Howrah as a stop on AC12; exact terminal name unconfirmed.
A11: WB-HOWRAH-SANTRAGACHIB-010 | B11: Santragachi Bus Terminus | C11: Bus Terminal | D11: Howrah | F11: West Bengal | H11: India | M11: N | N11: Y | O11: Unknown | Q11: Santragachi | R11: Howrah, Santragachi Bus Terminus, Santragachi, Howrah bus, Howrah bus stand, bus terminal Howrah, West Bengal | S11: https://obeta.ttef.in/topic/bus-terminus | T11: Telegraph (My Kolkata) - Bus Terminus topic page | U11: Partially Verified | V11: 46297 | W11: Name/location from secondary source; official confirmation, address and coordinates pending.
A12: WB-HOWRAH-SHALIMARBUST-011 | B12: Shalimar Bus Terminus | C12: Bus Terminal | D12: Howrah | F12: West Bengal | H12: India | M12: N | N12: Y | O12: Unknown | Q12: Shalimar | R12: Howrah, Shalimar Bus Terminus, Shalimar, Howrah bus, Howrah bus stand, bus terminal Howrah, West Bengal | U12: Needs Verification | W12: Included from general knowledge of the transport network; no source retrieved yet. Name, exact location and coordinates need verification.
A13: WB-HOWRAH-DEPOTSBSTC-012 | B13: Howrah Depot (SBSTC) | C13: Regional Bus Terminal | D13: Howrah | F13: West Bengal | H13: India | M13: N | N13: Y | O13: Y | P13: South Bengal State Transport Corporation | Q13: SBSTC Howrah Depot | R13: Howrah, Howrah Depot (SBSTC), SBSTC Howrah Depot, Howrah bus, Howrah bus stand, bus terminal Howrah, West Bengal | S13: https://www.makemytrip.com/bus-tickets/wbtc-ctc-from-kolkata-to-durgapur_west_bengal-online-bus-tickets.html | T13: MakeMyTrip - WBTC Kolkata to Durgapur | U13: Partially Verified | V13: 46297 | W13: Name/location from secondary source; official confirmation, address and coordinates pending.
A14: WB-SILIGURI-TENZINGNORGA-013 | B14: Tenzing Norgay Central Bus Terminus | C14: Central Bus Terminal | D14: Siliguri | F14: West Bengal | H14: India | M14: Y | N14: Y | O14: Unknown | Q14: Siliguri Bus Terminus, Siliguri Bus Stand, Tenzing Norgay Bus Terminus | R14: Siliguri, Tenzing Norgay Central Bus Terminus, Siliguri Bus Terminus, Siliguri Bus Stand, Tenzing Norgay Bus Terminus, Siliguri bus, Siliguri bus stand, bus terminal Siliguri, West Bengal | S14: https://obeta.ttef.in/topic/bus-terminus | T14: Telegraph (My Kolkata) - Bus Terminus topic page | U14: Partially Verified | V14: 46297 | W14: Name/location from secondary source; official confirmation, address and coordinates pending.
A15: WB-JALPAIGU-BUSSTAND-014 | B15: Jalpaiguri Bus Stand | C15: Bus Stand | D15: Jalpaiguri | F15: West Bengal | H15: India | M15: N | N15: Y | O15: Unknown | R15: Jalpaiguri, Jalpaiguri Bus Stand, Jalpaiguri bus, Jalpaiguri bus stand, bus terminal Jalpaiguri, West Bengal | U15: Needs Verification | W15: Included from general knowledge of the transport network; no source retrieved yet. Name, exact location and coordinates need verification.
A16: WB-COOCHBEH-BUSSTAND-015 | B16: Cooch Behar Bus Stand | C16: Bus Stand | D16: Cooch Behar | F16: West Bengal | H16: India | M16: N | N16: Y | O16: Unknown | Q16: Coochbehar Bus Stand, Cooch Behar NBSTC | R16: Cooch Behar, Cooch Behar Bus Stand, Coochbehar Bus Stand, Cooch Behar NBSTC, Cooch Behar bus, Cooch Behar bus stand, bus terminal Cooch Behar, West Bengal | U16: Needs Verification | W16: Included from general knowledge of the transport network; no source retrieved yet. Name, exact location and coordinates need verification.
A17: WB-ALIPURDU-BUSSTAND-016 | B17: Alipurduar Bus Stand | C17: Bus Stand | D17: Alipurduar | F17: West Bengal | H17: India | M17: N | N17: Y | O17: Unknown | R17: Alipurduar, Alipurduar Bus Stand, Alipurduar bus, Alipurduar bus stand, bus terminal Alipurduar, West Bengal | U17: Needs Verification | W17: Included from general knowledge of the transport network; no source retrieved yet. Name, exact location and coordinates need verification.
A18: WB-MALDA-BUSSTAND-017 | B18: Malda Bus Stand | C18: Bus Stand | D18: Malda | F18: West Bengal | H18: India | M18: N | N18: Y | O18: Unknown | Q18: English Bazar Bus Stand, Malda Town Bus Stand | R18: Malda, Malda Bus Stand, English Bazar Bus Stand, Malda Town Bus Stand, Malda bus, Malda bus stand, bus terminal Malda, West Bengal | U18: Needs Verification | W18: Included from general knowledge of the transport network; no source retrieved yet. Name, exact location and coordinates need verification.
A19: WB-RAIGANJ-BUSSTAND-018 | B19: Raiganj Bus Stand | C19: Bus Stand | D19: Raiganj | F19: West Bengal | H19: India | M19: N | N19: Y | O19: Unknown | Q19: Raiganj Bus Terminus | R19: Raiganj, Raiganj Bus Stand, Raiganj Bus Terminus, Raiganj bus, Raiganj bus stand, bus terminal Raiganj, West Bengal | U19: Needs Verification | W19: Included from general knowledge of the transport network; no source retrieved yet. Name, exact location and coordinates need verification.
A20: WB-BALURGHA-BUSSTAND-019 | B20: Balurghat Bus Stand | C20: Bus Stand | D20: Balurghat | F20: West Bengal | H20: India | M20: N | N20: Y | O20: Unknown | R20: Balurghat, Balurghat Bus Stand, Balurghat bus, Balurghat bus stand, bus terminal Balurghat, West Bengal | U20: Needs Verification | W20: Included from general knowledge of the transport network; no source retrieved yet. Name, exact location and coordinates need verification.
A21: WB-DARJEELI-BUSSTAND-020 | B21: Darjeeling Bus Stand | C21: Bus Stand | D21: Darjeeling | F21: West Bengal | H21: India | M21: N | N21: Y | O21: Unknown | Q21: Darjeeling Motor Stand | R21: Darjeeling, Darjeeling Bus Stand, Darjeeling Motor Stand, Darjeeling bus, Darjeeling bus stand, bus terminal Darjeeling, West Bengal | U21: Needs Verification | W21: Included from general knowledge of the transport network; no source retrieved yet. Name, exact location and coordinates need verification.
A22: WB-KALIMPON-BUSSTAND-021 | B22: Kalimpong Bus Stand | C22: Bus Stand | D22: Kalimpong | F22: West Bengal | H22: India | M22: N | N22: Y | O22: Unknown | Q22: Kalimpong Motor Stand | R22: Kalimpong, Kalimpong Bus Stand, Kalimpong Motor Stand, Kalimpong bus, Kalimpong bus stand, bus terminal Kalimpong, West Bengal | U22: Needs Verification | W22: Included from general knowledge of the transport network; no source retrieved yet. Name, exact location and coordinates need verification.
A23: WB-DURGAPUR-BUSSTAND-022 | B23: Durgapur Bus Stand | C23: Bus Stand | D23: Durgapur | F23: West Bengal | H23: India | M23: Y | N23: Y | O23: Unknown | Q23: Durgapur Bus Terminus, City Centre Durgapur Bus Stand | R23: Durgapur, Durgapur Bus Stand, Durgapur Bus Terminus, City Centre Durgapur Bus Stand, Durgapur bus, Durgapur bus stand, bus terminal Durgapur, West Bengal | U23: Needs Verification | W23: Included from general knowledge of the transport network; no source retrieved yet. Name, exact location and coordinates need verification.
A24: WB-ASANSOL-BUSSTAND-023 | B24: Asansol Bus Stand | C24: Bus Stand | D24: Asansol | F24: West Bengal | H24: India | M24: Y | N24: Y | O24: Unknown | Q24: Asansol Bus Terminus | R24: Asansol, Asansol Bus Stand, Asansol Bus Terminus, Asansol bus, Asansol bus stand, bus terminal Asansol, West Bengal | U24: Needs Verification | W24: Included from general knowledge of the transport network; no source retrieved yet. Name, exact location and coordinates need verification.
A25: WB-RANIGANJ-BUSSTAND-024 | B25: Raniganj Bus Stand | C25: Bus Stand | D25: Raniganj | F25: West Bengal | H25: India | M25: N | N25: Y | O25: Unknown | R25: Raniganj, Raniganj Bus Stand, Raniganj bus, Raniganj bus stand, bus terminal Raniganj, West Bengal | U25: Needs Verification | W25: Included from general knowledge of the transport network; no source retrieved yet. Name, exact location and coordinates need verification.
A26: WB-BARDHAMA-BUSSTAND-025 | B26: Bardhaman Bus Stand | C26: Bus Stand | D26: Bardhaman | F26: West Bengal | H26: India | M26: Y | N26: Y | O26: Unknown | Q26: Burdwan Bus Stand | R26: Bardhaman, Bardhaman Bus Stand, Burdwan Bus Stand, Bardhaman bus, Bardhaman bus stand, bus terminal Bardhaman, West Bengal | U26: Needs Verification | W26: Included from general knowledge of the transport network; no source retrieved yet. Name, exact location and coordinates need verification.
A27: WB-BOLPUR-BUSSTAND-026 | B27: Bolpur Bus Stand | C27: Bus Stand | D27: Bolpur | F27: West Bengal | H27: India | M27: N | N27: Y | O27: Unknown | Q27: Santiniketan Bus Stand | R27: Bolpur, Bolpur Bus Stand, Santiniketan Bus Stand, Bolpur bus, Bolpur bus stand, bus terminal Bolpur, West Bengal | U27: Needs Verification | W27: Included from general knowledge of the transport network; no source retrieved yet. Name, exact location and coordinates need verification.
A28: WB-SURI-BUSSTAND-027 | B28: Suri Bus Stand | C28: Bus Stand | D28: Suri | F28: West Bengal | H28: India | M28: N | N28: Y | O28: Unknown | R28: Suri, Suri Bus Stand, Suri bus, Suri bus stand, bus terminal Suri, West Bengal | U28: Needs Verification | W28: Included from general knowledge of the transport network; no source retrieved yet. Name, exact location and coordinates need verification.
A29: WB-RAMPURHA-BUSSTAND-028 | B29: Rampurhat Bus Stand | C29: Bus Stand | D29: Rampurhat | F29: West Bengal | H29: India | M29: N | N29: Y | O29: Unknown | R29: Rampurhat, Rampurhat Bus Stand, Rampurhat bus, Rampurhat bus stand, bus terminal Rampurhat, West Bengal | U29: Needs Verification | W29: Included from general knowledge of the transport network; no source retrieved yet. Name, exact location and coordinates need verification.
A30: WB-KHARAGPU-BUSSTAND-029 | B30: Kharagpur Bus Stand | C30: Bus Stand | D30: Kharagpur | F30: West Bengal | H30: India | M30: N | N30: Y | O30: Unknown | R30: Kharagpur, Kharagpur Bus Stand, Kharagpur bus, Kharagpur bus stand, bus terminal Kharagpur, West Bengal | U30: Needs Verification | W30: Included from general knowledge of the transport network; no source retrieved yet. Name, exact location and coordinates need verification.
A31: WB-MIDNAPOR-BUSSTAND-030 | B31: Midnapore Bus Stand | C31: Bus Stand | D31: Midnapore | F31: West Bengal | H31: India | M31: N | N31: Y | O31: Unknown | Q31: Medinipur Bus Stand | R31: Midnapore, Midnapore Bus Stand, Medinipur Bus Stand, Midnapore bus, Midnapore bus stand, bus terminal Midnapore, West Bengal | U31: Needs Verification | W31: Included from general knowledge of the transport network; no source retrieved yet. Name, exact location and coordinates need verification.
A32: WB-JHARGRAM-BUSSTAND-031 | B32: Jhargram Bus Stand | C32: Bus Stand | D32: Jhargram | F32: West Bengal | H32: India | M32: N | N32: Y | O32: Unknown | R32: Jhargram, Jhargram Bus Stand, Jhargram bus, Jhargram bus stand, bus terminal Jhargram, West Bengal | U32: Needs Verification | W32: Included from general knowledge of the transport network; no source retrieved yet. Name, exact location and coordinates need verification.
A33: WB-BANKURA-BUSSTAND-032 | B33: Bankura Bus Stand | C33: Bus Stand | D33: Bankura | F33: West Bengal | H33: India | M33: N | N33: Y | O33: Unknown | R33: Bankura, Bankura Bus Stand, Bankura bus, Bankura bus stand, bus terminal Bankura, West Bengal | U33: Needs Verification | W33: Included from general knowledge of the transport network; no source retrieved yet. Name, exact location and coordinates need verification.
A34: WB-BISHNUPU-BUSSTAND-033 | B34: Bishnupur Bus Stand | C34: Bus Stand | D34: Bishnupur | F34: West Bengal | H34: India | M34: N | N34: Y | O34: Unknown | R34: Bishnupur, Bishnupur Bus Stand, Bishnupur bus, Bishnupur bus stand, bus terminal Bishnupur, West Bengal | U34: Needs Verification | W34: Included from general knowledge of the transport network; no source retrieved yet. Name, exact location and coordinates need verification.
A35: WB-PURULIA-BUSSTAND-034 | B35: Purulia Bus Stand | C35: Bus Stand | D35: Purulia | F35: West Bengal | H35: India | M35: N | N35: Y | O35: Unknown | R35: Purulia, Purulia Bus Stand, Purulia bus, Purulia bus stand, bus terminal Purulia, West Bengal | U35: Needs Verification | W35: Included from general knowledge of the transport network; no source retrieved yet. Name, exact location and coordinates need verification.
A36: WB-ARAMBAGH-BUSSTAND-035 | B36: Arambagh Bus Stand | C36: Bus Stand | D36: Arambagh | F36: West Bengal | H36: India | M36: N | N36: Y | O36: Unknown | Q36: Arambag Bus Stand | R36: Arambagh, Arambagh Bus Stand, Arambag Bus Stand, Arambagh bus, Arambagh bus stand, bus terminal Arambagh, West Bengal | U36: Needs Verification | W36: Included from general knowledge of the transport network; no source retrieved yet. Name, exact location and coordinates need verification.
A37: WB-DIGHA-BUSSTAND-036 | B37: Digha Bus Stand | C37: Bus Stand | D37: Digha | F37: West Bengal | H37: India | M37: N | N37: Y | O37: Unknown | Q37: New Digha Bus Stand | R37: Digha, Digha Bus Stand, New Digha Bus Stand, Digha bus, Digha bus stand, bus terminal Digha, West Bengal | U37: Needs Verification | W37: Included from general knowledge of the transport network; no source retrieved yet. Name, exact location and coordinates need verification.
A38: WB-HALDIA-BUSSTAND-037 | B38: Haldia Bus Stand | C38: Bus Stand | D38: Haldia | F38: West Bengal | H38: India | M38: N | N38: Y | O38: Unknown | R38: Haldia, Haldia Bus Stand, Haldia bus, Haldia bus stand, bus terminal Haldia, West Bengal | U38: Needs Verification | W38: Included from general knowledge of the transport network; no source retrieved yet. Name, exact location and coordinates need verification.
A39: WB-TAMLUK-BUSSTAND-038 | B39: Tamluk Bus Stand | C39: Bus Stand | D39: Tamluk | F39: West Bengal | H39: India | M39: N | N39: Y | O39: Unknown | R39: Tamluk, Tamluk Bus Stand, Tamluk bus, Tamluk bus stand, bus terminal Tamluk, West Bengal | U39: Needs Verification | W39: Included from general knowledge of the transport network; no source retrieved yet. Name, exact location and coordinates need verification.
A40: WB-BERHAMPO-BUSSTAND-039 | B40: Berhampore Bus Stand | C40: Bus Stand | D40: Berhampore | F40: West Bengal | H40: India | M40: Y | N40: Y | O40: Unknown | Q40: Baharampur Bus Stand | R40: Berhampore, Berhampore Bus Stand, Baharampur Bus Stand, Berhampore bus, Berhampore bus stand, bus terminal Berhampore, West Bengal | U40: Needs Verification | W40: Included from general knowledge of the transport network; no source retrieved yet. Name, exact location and coordinates need verification.
...

Sheet Cities
A1: City_ID | B1: City_Name | C1: District | D1: State | E1: Union_Territory | F1: Latitude | G1: Longitude | H1: Major_City | I1: Major_Bus_Hub | J1: Search_Name | K1: Alternate_Names | L1: Source_URL
A2: WB-CITY-ALIPURDUAR-0001 | B2: Alipurduar | D2: West Bengal | H2: N | I2: N | J2: alipurduar
A3: WB-CITY-ARAMBAGH-0002 | B3: Arambagh | D3: West Bengal | H3: N | I3: N | J3: arambagh
A4: WB-CITY-ASANSOL-0003 | B4: Asansol | D4: West Bengal | H4: Y | I4: Y | J4: asansol
A5: WB-CITY-BALURGHAT-0004 | B5: Balurghat | D5: West Bengal | H5: N | I5: N | J5: balurghat
A6: WB-CITY-BANKURA-0005 | B6: Bankura | D6: West Bengal | H6: N | I6: N | J6: bankura
A7: WB-CITY-BARASAT-0006 | B7: Barasat | D7: West Bengal | H7: N | I7: N | J7: barasat
A8: WB-CITY-BARDHAMAN-0007 | B8: Bardhaman | D8: West Bengal | H8: Y | I8: Y | J8: bardhaman, burdwan | K8: Burdwan
A9: WB-CITY-BASIRHAT-0008 | B9: Basirhat | D9: West Bengal | H9: N | I9: N | J9: basirhat
A10: WB-CITY-BERHAMPORE-0009 | B10: Berhampore | D10: West Bengal | H10: N | I10: Y | J10: berhampore, baharampur | K10: Baharampur
A11: WB-CITY-BISHNUPUR-0010 | B11: Bishnupur | D11: West Bengal | H11: N | I11: N | J11: bishnupur
A12: WB-CITY-BOLPUR-0011 | B12: Bolpur | D12: West Bengal | H12: N | I12: N | J12: bolpur
A13: WB-CITY-COOCHBEHAR-0012 | B13: Cooch Behar | D13: West Bengal | H13: N | I13: N | J13: cooch behar
A14: WB-CITY-DARJEELING-0013 | B14: Darjeeling | D14: West Bengal | H14: N | I14: N | J14: darjeeling
A15: WB-CITY-DHULIAN-0014 | B15: Dhulian | D15: West Bengal | H15: N | I15: N | J15: dhulian
A16: WB-CITY-DIGHA-0015 | B16: Digha | D16: West Bengal | H16: N | I16: N | J16: digha
A17: WB-CITY-DURGAPUR-0016 | B17: Durgapur | D17: West Bengal | H17: Y | I17: Y | J17: durgapur
A18: WB-CITY-HALDIA-0017 | B18: Haldia | D18: West Bengal | H18: N | I18: N | J18: haldia
A19: WB-CITY-HOWRAH-0018 | B19: Howrah | D19: West Bengal | H19: Y | I19: N | J19: howrah
A20: WB-CITY-JALPAIGURI-0019 | B20: Jalpaiguri | D20: West Bengal | H20: N | I20: N | J20: jalpaiguri
A21: WB-CITY-JHARGRAM-0020 | B21: Jhargram | D21: West Bengal | H21: N | I21: N | J21: jhargram
A22: WB-CITY-KALIMPONG-0021 | B22: Kalimpong | D22: West Bengal | H22: N | I22: N | J22: kalimpong
... A24: WB-CITY-KHARAGPUR-0023 | B24: Kharagpur | D24: West Bengal | H24: N | I24: N | J24: kharagpur
A25: WB-CITY-KOLKATA-0024 | B25: Kolkata | D25: West Bengal | H25: Y | I25: Y | J25: kolkata, calcutta | K25: Calcutta
A26: WB-CITY-KRISHNANAGAR-0025 | B26: Krishnanagar | D26: West Bengal | H26: N | I26: N | J26: krishnanagar
A27: WB-CITY-MALDA-0026 | B27: Malda | D27: West Bengal | H27: N | I27: N | J27: malda
A28: WB-CITY-MAYAPUR-0027 | B28: Mayapur | D28: West Bengal | H28: N | I28: N | J28: mayapur
A29: WB-CITY-MIDNAPORE-0028 | B29: Midnapore | D29: West Bengal | H29: N | I29: N | J29: midnapore, medinipur | K29: Medinipur
A30: WB-CITY-PURULIA-0029 | B30: Purulia | D30: West Bengal | H30: N | I30: N | J30: purulia
A31: WB-CITY-RAIGANJ-0030 | B31: Raiganj | D31: West Bengal | H31: N | I31: N | J31: raiganj
A32: WB-CITY-RAMPURHAT-0031 | B32: Rampurhat | D32: West Bengal | H32: N | I32: N | J32: rampurhat
A33: WB-CITY-RANIGANJ-0032 | B33: Raniganj | D33: West Bengal | H33: N | I33: N | J33: raniganj
A34: WB-CITY-SILIGURI-0033 | B34: Siliguri | D34: West Bengal | H34: Y | I34: Y | J34: siliguri
A35: WB-CITY-SURI-0034 | B35: Suri | D35: West Bengal | H35: N | I35: N | J35: suri
A36: WB-CITY-TAMLUK-0035 | B36: Tamluk | D36: West Bengal | H36: N | I36: N | J36: tamluk
A37: AP-CITY-ANANTAPUR-0036 | B37: Anantapur | D37: Andhra Pradesh | H37: N | I37: N | J37: anantapur
A38: AP-CITY-GUNTUR-0037 | B38: Guntur | D38: Andhra Pradesh | H38: Y | I38: Y | J38: guntur
A39: AP-CITY-KADAPA-0038 | B39: Kadapa | D39: Andhra Pradesh | H39: N | I39: N | J39: kadapa
A40: AP-CITY-KAKINADA-0039 | B40: Kakinada | D40: Andhra Pradesh | H40: N | I40: N | J40: kakinada
A41: AP-CITY-KURNOOL-0040 | B41: Kurnool | D41: Andhra Pradesh | H41: N | I41: N | J41: kurnool
...

Sheet Bus_Routes
A1: Route_ID | B1: Origin_Terminal_ID | C1: Origin_Name | D1: Origin_City | E1: Origin_State | F1: Destination_Terminal_ID | G1: Destination_Name | H1: Destination_City | I1: Destination_State | J1: Route_Name | K1: Route_Type | L1: Intermediate_Cities | M1: Approx_Distance_KM | N1: Approx_Duration | O1: Operator | P1: Service_Type | Q1: Frequency | R1: Days_Operating | S1: Source_URL | T1: Source_Name | U1: Verification_Status | V1: Last_Verified | W1: Notes
A2: WB-RT-001 | C2: Kolkata (Esplanade area, per listing) | D2: Kolkata | E2: West Bengal | G2: Bolpur | H2: Bolpur | I2: West Bengal | J2: Kolkata - Bolpur | K2: Intrastate | O2: West Bengal Transport Corporation | P2: State Transport | S2: https://www.makemytrip.com/bus-tickets/wbtc-ctc-from-kolkata-to-bolpur-online-bus-tickets.html | T2: MakeMyTrip - WBTC Kolkata to Bolpur | U2: Partially Verified | V2: 46297 | W2: Source is a booking-portal listing snapshot; terminal not specified, so terminal IDs left blank. Distance/duration not stated in source.
A3: WB-RT-002 | C3: Kolkata | D3: Kolkata | E3: West Bengal | G3: Durgapur | H3: Durgapur | I3: West Bengal | J3: Kolkata - Durgapur | K3: Intrastate | O3: SBSTC / WBTC | P3: State Transport | Q3: Multiple daily (listing shows e.g. 16:15 Durgapur departure) | S3: https://www.makemytrip.com/bus-tickets/wbtc-ctc-from-kolkata-to-durgapur_west_bengal-online-bus-tickets.html | T3: MakeMyTrip - WBTC Kolkata to Durgapur | U3: Partially Verified | V3: 46297 | W3: Source is a booking-portal listing snapshot; terminal not specified, so terminal IDs left blank. Distance/duration not stated in source.
A4: WB-RT-003 | B4: WB-HOWRAH-DEPOTSBSTC-012 | C4: Kolkata (Howrah Depot) | D4: Kolkata | E4: West Bengal | G4: Asansol | H4: Asansol | I4: West Bengal | J4: Kolkata - Asansol | K4: Intrastate | O4: SBSTC | P4: State Transport | Q4: Multiple daily (listing shows 05:30, 06:15, 10:30, 07:50 AC) | S4: https://www.makemytrip.com/bus-tickets/wbtc-ctc-from-kolkata-to-durgapur_west_bengal-online-bus-tickets.html | T4: MakeMyTrip - WBTC Kolkata to Durgapur | U4: Partially Verified | V4: 46297 | W4: Source is a booking-portal listing snapshot; terminal not specified, so terminal IDs left blank. Distance/duration not stated in source.
A5: WB-RT-004 | C5: Kolkata | D5: Kolkata | E5: West Bengal | G5: Arambagh | H5: Arambagh | I5: West Bengal | J5: Kolkata - Arambagh (non-stop and ordinary) | K5: Intrastate | O5: SBSTC | P5: State Transport | Q5: Multiple daily (about 11 departures listed, 06:30-16:30) | S5: https://www.makemytrip.com/bus-tickets/wbtc-ctc-from-kolkata-to-arambagh-online-bus-tickets.html | T5: MakeMyTrip - WBTC Kolkata to Arambagh | U5: Partially Verified | V5: 46297 | W5: Source is a booking-portal listing snapshot; terminal not specified, so terminal IDs left blank. Distance/duration not stated in source.
A6: WB-RT-005 | C6: Kolkata | D6: Kolkata | E6: West Bengal | G6: Bishnupur | H6: Bishnupur | I6: West Bengal | J6: Kolkata - Joyrambati - Bishnupur | K6: Intrastate | L6: Joyrambati | O6: West Bengal Transport Corporation | P6: State Transport | S6: https://www.makemytrip.com/bus-tickets/wbtc-ctc-from-kolkata-to-arambagh-online-bus-tickets.html | T6: MakeMyTrip - WBTC Kolkata to Arambagh | U6: Partially Verified | V6: 46297 | W6: Source is a booking-portal listing snapshot; terminal not specified, so terminal IDs left blank. Distance/duration not stated in source. Intermediate stop from service name.
A7: WB-RT-006 | C7: Kolkata | D7: Kolkata | E7: West Bengal | G7: Purulia | H7: Purulia | I7: West Bengal | J7: Kolkata - Asansol - Purulia (AC Volvo, Banglashree Express) | K7: Long Distance | L7: Asansol | O7: West Bengal Transport Corporation | P7: AC Volvo | S7: https://www.makemytrip.com/bus-tickets/wbtc-ctc-from-kolkata-to-purulia-online-bus-tickets.html | T7: MakeMyTrip - WBTC Kolkata to Purulia | U7: Partially Verified | V7: 46297 | W7: Source is a booking-portal listing snapshot; terminal not specified, so terminal IDs left blank. Distance/duration not stated in source.
A8: WB-RT-007 | B8: WB-HOWRAH-DEPOTSBSTC-012 | C8: Kolkata (Howrah Depot) | D8: Kolkata | E8: West Bengal | G8: Purulia | H8: Purulia | I8: West Bengal | J8: Kolkata - Bankura - Purulia | K8: Long Distance | L8: Bankura | O8: SBSTC | P8: State Transport | Q8: Daily (listing shows 12:00 from Howrah) | S8: https://www.makemytrip.com/bus-tickets/wbtc-ctc-from-kolkata-to-purulia-online-bus-tickets.html | T8: MakeMyTrip - WBTC Kolkata to Purulia | U8: Partially Verified | V8: 46297 | W8: Source is a booking-portal listing snapshot; terminal not specified, so terminal IDs left blank. Distance/duration not stated in source.
A9: WB-RT-008 | B9: WB-HOWRAH-DEPOTSBSTC-012 | C9: Kolkata (Howrah Depot) | D9: Kolkata | E9: West Bengal | G9: Purulia | H9: Purulia | I9: West Bengal | J9: Kolkata - Asansol - Purulia (ordinary) | K9: Long Distance | L9: Asansol | O9: SBSTC | P9: State Transport | Q9: Daily (listing shows 11:00 from Howrah) | S9: https://www.makemytrip.com/bus-tickets/wbtc-ctc-from-kolkata-to-purulia-online-bus-tickets.html | T9: MakeMyTrip - WBTC Kolkata to Purulia | U9: Partially Verified | V9: 46297 | W9: Source is a booking-portal listing snapshot; terminal not specified, so terminal IDs left blank. Distance/duration not stated in source.
A10: WB-RT-009 | C10: Kolkata | D10: Kolkata | E10: West Bengal | G10: Digha | H10: Digha | I10: West Bengal | J10: Kolkata - Digha | K10: Intrastate | O10: West Bengal Transport Corporation | P10: State Transport | S10: https://www.makemytrip.com/bus-tickets/wbtc-ctc-from-kolkata-to-durgapur_west_bengal-online-bus-tickets.html | T10: MakeMyTrip - WBTC Kolkata to Durgapur | U10: Partially Verified | V10: 46297 | W10: Named in the WBTC "popular routes" list on the MakeMyTrip WBTC page; individual schedule not retrieved.
A11: WB-RT-010 | C11: Kolkata | D11: Kolkata | E11: West Bengal | G11: Mayapur | H11: Mayapur | I11: West Bengal | J11: Kolkata - Mayapur | K11: Intrastate | O11: West Bengal Transport Corporation | P11: State Transport | S11: https://www.makemytrip.com/bus-tickets/wbtc-ctc-from-kolkata-to-durgapur_west_bengal-online-bus-tickets.html | T11: MakeMyTrip - WBTC Kolkata to Durgapur | U11: Partially Verified | V11: 46297 | W11: Named in the WBTC "popular routes" list on the MakeMyTrip WBTC page; individual schedule not retrieved.
A12: WB-RT-011 | C12: Kolkata | D12: Kolkata | E12: West Bengal | G12: Raniganj | H12: Raniganj | I12: West Bengal | J12: Kolkata - Raniganj | K12: Intrastate | O12: West Bengal Transport Corporation | P12: State Transport | S12: https://www.makemytrip.com/bus-tickets/wbtc-ctc-from-kolkata-to-durgapur_west_bengal-online-bus-tickets.html | T12: MakeMyTrip - WBTC Kolkata to Durgapur | U12: Partially Verified | V12: 46297 | W12: Named in the WBTC "popular routes" list on the MakeMyTrip WBTC page; individual schedule not retrieved.
A13: WB-RT-012 | C13: Kolkata | D13: Kolkata | E13: West Bengal | G13: Suri | H13: Suri | I13: West Bengal | J13: Kolkata - Suri | K13: Intrastate | O13: West Bengal Transport Corporation | P13: State Transport | S13: https://www.makemytrip.com/bus-tickets/wbtc-ctc-from-kolkata-to-durgapur_west_bengal-online-bus-tickets.html | T13: MakeMyTrip - WBTC Kolkata to Durgapur | U13: Partially Verified | V13: 46297 | W13: Named in the WBTC "popular routes" list on the MakeMyTrip WBTC page; individual schedule not retrieved.
A14: WB-RT-013 | C14: Kolkata | D14: Kolkata | E14: West Bengal | G14: Balurghat | H14: Balurghat | I14: West Bengal | J14: Kolkata - Balurghat | K14: Intrastate | O14: West Bengal Transport Corporation | P14: State Transport | S14: https://www.makemytrip.com/bus-tickets/wbtc-ctc-from-kolkata-to-durgapur_west_bengal-online-bus-tickets.html | T14: MakeMyTrip - WBTC Kolkata to Durgapur | U14: Partially Verified | V14: 46297 | W14: Named in the WBTC "popular routes" list on the MakeMyTrip WBTC page; individual schedule not retrieved.
A15: WB-RT-014 | B15: WB-ASANSOL-BUSSTAND-023 | C15: Asansol | D15: Asansol | E15: West Bengal | G15: Kolkata Airport | H15: Kolkata | I15: West Bengal | J15: Asansol - Kolkata Airport | K15: Airport Connection | O15: West Bengal Transport Corporation | P15: State Transport | S15: https://www.makemytrip.com/bus-tickets/wbtc-ctc-from-kolkata-to-durgapur_west_bengal-online-bus-tickets.html | T15: MakeMyTrip - WBTC Kolkata to Durgapur | U15: Partially Verified | V15: 46297 | W15: Named in the WBTC "popular routes" list on the MakeMyTrip WBTC page; individual schedule not retrieved. Airport stop name from source; no airport terminal row exists yet.
A16: WB-RT-015 | B16: WB-KOLKATA-NARAYANPURBU-005 | C16: Narayanpur Bus Terminal | D16: Kolkata | E16: West Bengal | F16: WB-KOLKATA-BABUGHATBUST-002 | G16: Babughat Bus Terminus | H16: Kolkata | I16: West Bengal | J16: WBTC 217 (CSTC): Narayanpur - Babughat | K16: Regional | L16: Esplanade | O16: West Bengal Transport Corporation | P16: City Bus | Q16: First bus about 05:40, last about 23:00 (Narayanpur end) | R16: Daily (not stated) | S16: https://housing.com/news/217-bus-route-kolkata-narayanpur-to-babughat | T16: housing.com - 217 bus route Kolkata | U16: Partially Verified | V16: 46297 | W16: Kolkata city route; first/last timings and stop count from a secondary portal. Passes Esplanade.
A17: WB-RT-016 | B17: WB-KOLKATA-BANSDRONIBUS-006 | C17: Bansdroni Bus Terminal | D17: Kolkata | E17: West Bengal | F17: WB-KOLKATA-BABUGHATBUST-002 | G17: Babughat Bus Terminus | H17: Kolkata | I17: West Bengal | J17: WBTC 205: Bansdroni - Babughat | K17: Regional | L17: Esplanade | O17: West Bengal Transport Corporation | P17: City Bus | Q17: First bus about 06:00, last about 22:45 | R17: Daily (not stated) | S17: https://housing.com/news/205-bus-route-in-kolkata-bansdroni-to-babughat | T17: housing.com - 205 bus route Kolkata | U17: Partially Verified | V17: 46297 | W17: Kolkata city route; first/last timings and stop count from a secondary portal. Source calls it a private city bus while attributing it to WBTC - operator needs checking.
A18: WB-RT-017 | B18: WB-KOLKATA-SHAPOORJIBUS-004 | C18: Shapoorji Bus Terminal | D18: Kolkata | E18: West Bengal | F18: WB-KOLKATA-HOWRAHBUSSTA-009 | G18: Howrah Bus Stand | H18: Howrah | I18: West Bengal | J18: WBTC AC12: Shapoorji - Howrah | K18: Regional | L18: Esplanade | O18: West Bengal Transport Corporation | P18: AC City Bus | S18: https://housing.com/news/ac-12-bus-route-kolkata-shapoorji-to-howrah/ | T18: housing.com - AC12 bus route Kolkata | U18: Partially Verified | V18: 46297 | W18: Kolkata city route; first/last timings and stop count from a secondary portal.

Sheet Interstate_Routes
A1: Interstate_Route_ID | B1: Origin_State | C1: Origin_City | D1: Origin_Terminal | E1: Destination_State | F1: Destination_City | G1: Destination_Terminal | H1: Route_Name | I1: Intermediate_States | J1: Intermediate_Cities | K1: Approx_Distance_KM | L1: Approx_Duration | M1: Operator | N1: Service_Type | O1: Frequency | P1: Source_URL | Q1: Verification_Status | R1: Notes | S1: Origin_Terminal_ID | T1: Destination_Terminal_ID
A2: IN-RT-001 | B2: West Bengal | C2: Kolkata | D2: Kolkata (terminal not stated) | E2: Bihar | F2: Patna | G2: Patna (terminal not stated) | H2: Kolkata - Patna | M2: Bihar State Road Transport Corporation | N2: Festive special | O2: Departures at 6:00 pm, 7:30 pm and 8:30 pm | P2: https://patnapress.com/bsrtc-festive-season-bus-services/; https://patnapress.com/bihar-special-festive-buses/ | Q2: Partially Verified | R2: Reported as a festive-season special (Durga Puja/Diwali/Chhath); regular year-round operation not confirmed. Source is regional news, not the corporation itself. Intermediate states/cities, distance and duration not stated.
A3: IN-RT-002 | B3: West Bengal | C3: Kolkata | D3: Kolkata (terminal not stated) | E3: Bihar | F3: Bhagalpur | G3: Bhagalpur (terminal not stated) | H3: Kolkata - Bhagalpur | M3: Bihar State Road Transport Corporation | N3: Festive special | O3: Evening services | P3: https://patnapress.com/bihar-special-festive-buses/ | Q3: Partially Verified | R3: Reported as a festive-season special (Durga Puja/Diwali/Chhath); regular year-round operation not confirmed. Source is regional news, not the corporation itself. Intermediate states/cities, distance and duration not stated.
A4: IN-RT-003 | B4: Bihar | C4: Patna | D4: Patna (terminal not stated) | E4: Delhi | F4: Delhi | G4: Anand Vihar ISBT | H4: Patna - Anand Vihar (Delhi) | M4: Bihar State Road Transport Corporation | N4: Festive special | O4: Departures between 2 pm and 8 pm (all five origins combined, about 65 buses daily) | P4: https://patnapress.com/bsrtc-festive-season-bus-services/ | Q4: Partially Verified | R4: Reported as a festive-season special (Durga Puja/Diwali/Chhath); regular year-round operation not confirmed. Source is regional news, not the corporation itself. Intermediate states/cities, distance and duration not stated. Source names the Delhi destination as Anand Vihar. | T4: DL-DELHI-ANANDVIHARIS-002
A5: IN-RT-004 | B5: Bihar | C5: Muzaffarpur | D5: Muzaffarpur (terminal not stated) | E5: Delhi | F5: Delhi | G5: Anand Vihar ISBT | H5: Muzaffarpur - Anand Vihar (Delhi) | M5: Bihar State Road Transport Corporation | N5: Festive special | O5: Departures between 2 pm and 8 pm (all five origins combined, about 65 buses daily) | P5: https://patnapress.com/bsrtc-festive-season-bus-services/ | Q5: Partially Verified | R5: Reported as a festive-season special (Durga Puja/Diwali/Chhath); regular year-round operation not confirmed. Source is regional news, not the corporation itself. Intermediate states/cities, distance and duration not stated. Source names the Delhi destination as Anand Vihar. | T5: DL-DELHI-ANANDVIHARIS-002
A6: IN-RT-005 | B6: Bihar | C6: Purnia | D6: Purnia (terminal not stated) | E6: Delhi | F6: Delhi | G6: Anand Vihar ISBT | H6: Purnia - Anand Vihar (Delhi) | M6: Bihar State Road Transport Corporation | N6: Festive special | O6: Departures between 2 pm and 8 pm (all five origins combined, about 65 buses daily) | P6: https://patnapress.com/bsrtc-festive-season-bus-services/ | Q6: Partially Verified | R6: Reported as a festive-season special (Durga Puja/Diwali/Chhath); regular year-round operation not confirmed. Source is regional news, not the corporation itself. Intermediate states/cities, distance and duration not stated. Source names the Delhi destination as Anand Vihar. | T6: DL-DELHI-ANANDVIHARIS-002
A7: IN-RT-006 | B7: Bihar | C7: Gaya | D7: Gaya (terminal not stated) | E7: Delhi | F7: Delhi | G7: Anand Vihar ISBT | H7: Gaya - Anand Vihar (Delhi) | M7: Bihar State Road Transport Corporation | N7: Festive special | O7: Departures between 2 pm and 8 pm (all five origins combined, about 65 buses daily) | P7: https://patnapress.com/bsrtc-festive-season-bus-services/ | Q7: Partially Verified | R7: Reported as a festive-season special (Durga Puja/Diwali/Chhath); regular year-round operation not confirmed. Source is regional news, not the corporation itself. Intermediate states/cities, distance and duration not stated. Source names the Delhi destination as Anand Vihar. | T7: DL-DELHI-ANANDVIHARIS-002
A8: IN-RT-007 | B8: Bihar | C8: Darbhanga | D8: Darbhanga (terminal not stated) | E8: Delhi | F8: Delhi | G8: Anand Vihar ISBT | H8: Darbhanga - Anand Vihar (Delhi) | M8: Bihar State Road Transport Corporation | N8: Festive special | O8: Departures between 2 pm and 8 pm (all five origins combined, about 65 buses daily) | P8: https://patnapress.com/bsrtc-festive-season-bus-services/ | Q8: Partially Verified | R8: Reported as a festive-season special (Durga Puja/Diwali/Chhath); regular year-round operation not confirmed. Source is regional news, not the corporation itself. Intermediate states/cities, distance and duration not stated. Source names the Delhi destination as Anand Vihar. | T8: DL-DELHI-ANANDVIHARIS-002
A9: IN-RT-008 | B9: Bihar | C9: Patna | D9: Patna (terminal not stated) | E9: Uttar Pradesh | F9: Ghaziabad | G9: Ghaziabad (terminal not stated) | H9: Patna - Ghaziabad (Volvo) | M9: Bihar State Road Transport Corporation | N9: AC Volvo | P9: https://en.wikipedia.org/wiki/Bihar_State_Road_Transport_Corporation | Q9: Partially Verified | R9: Volvo service described on the BSRTC Wikipedia page as recently started; current schedule not verified. Destination given as Ghaziabad (Delhi NCR); terminal not stated.
A10: IN-RT-009 | B10: Bihar | C10: Kishanganj | D10: Kishanganj (terminal not stated) | E10: Uttar Pradesh | F10: Ghaziabad | G10: Ghaziabad (terminal not stated) | H10: Kishanganj - Ghaziabad (Volvo) | M10: Bihar State Road Transport Corporation | N10: AC Volvo | P10: https://en.wikipedia.org/wiki/Bihar_State_Road_Transport_Corporation | Q10: Partially Verified | R10: Volvo service described on the BSRTC Wikipedia page as recently started; current schedule not verified. Destination given as Ghaziabad (Delhi NCR); terminal not stated.

Sheet Bus_Operators
A1: Operator_ID | B1: Operator_Name | C1: Operator_Type | D1: State | E1: Headquarters | F1: Website | G1: Source_URL | H1: Verification_Status | I1: Notes
A2: WBTC | B2: West Bengal Transport Corporation | C2: State Transport | D2: West Bengal | E2: Kolkata | F2: https://wbtc.co.in | G2: https://en.wikipedia.com/wiki/WBSTC | H2: Partially Verified | I2: Existence/name from secondary source; official site, HQ and coverage to be confirmed.
A3: SBSTC | B3: South Bengal State Transport Corporation | C3: State Transport | D3: West Bengal | E3: Kolkata | G3: https://www.makemytrip.com/bus-tickets/wbtc-ctc-from-kolkata-to-arambagh-online-bus-tickets.html | H3: Partially Verified | I3: Existence/name from secondary source; official site, HQ and coverage to be confirmed.
A4: NBSTC | B4: North Bengal State Transport Corporation | C4: State Transport | D4: West Bengal | E4: Coochbehar | H4: Needs Verification | I4: Widely known state transport undertaking listed from general knowledge; no source retrieved yet. Name/HQ/website need verification.
A5: APSRTC | B5: Andhra Pradesh State Road Transport Corporation | C5: State Transport | D5: Andhra Pradesh | E5: Vijayawada | H5: Needs Verification | I5: Widely known state transport undertaking listed from general knowledge; no source retrieved yet. Name/HQ/website need verification.
A6: APST | B6: Arunachal Pradesh State Transport | C6: State Transport | D6: Arunachal Pradesh | E6: Itanagar | H6: Needs Verification | I6: Widely known state transport undertaking listed from general knowledge; no source retrieved yet. Name/HQ/website need verification.
A7: ASTC | B7: Assam State Transport Corporation | C7: State Transport | D7: Assam | E7: Guwahati | H7: Needs Verification | I7: Widely known state transport undertaking listed from general knowledge; no source retrieved yet. Name/HQ/website need verification.
A8: BSRTC | B8: Bihar State Road Transport Corporation | C8: State Transport | D8: Bihar | E8: Patna | F8: https://bsrtc.co.in | G8: https://en.wikipedia.org/wiki/Bihar_State_Road_Transport_Corporation | H8: Partially Verified | I8: Existence/name from secondary source; official site, HQ and coverage to be confirmed.
A9: CGSRTC | B9: Chhattisgarh State Road Transport Corporation | C9: State Transport | D9: Chhattisgarh | E9: Raipur | H9: Needs Verification | I9: Widely known state transport undertaking listed from general knowledge; no source retrieved yet. Name/HQ/website need verification.
A10: KTCL | B10: Kadamba Transport Corporation Limited | C10: State Transport | D10: Goa | E10: Panaji | H10: Needs Verification | I10: Widely known state transport undertaking listed from general knowledge; no source retrieved yet. Name/HQ/website need verification.
A11: GSRTC | B11: Gujarat State Road Transport Corporation | C11: State Transport | D11: Gujarat | E11: Ahmedabad | H11: Needs Verification | I11: Widely known state transport undertaking listed from general knowledge; no source retrieved yet. Name/HQ/website need verification.
A12: HRYR | B12: Haryana Roadways | C12: State Transport | D12: Haryana | E12: Chandigarh | H12: Needs Verification | I12: Widely known state transport undertaking listed from general knowledge; no source retrieved yet. Name/HQ/website need verification.
A13: HRTC | B13: Himachal Road Transport Corporation | C13: State Transport | D13: Himachal Pradesh | E13: Shimla | H13: Needs Verification | I13: Widely known state transport undertaking listed from general knowledge; no source retrieved yet. Name/HQ/website need verification.
A14: JSRTC | B14: Jharkhand State Road Transport Corporation | C14: State Transport | D14: Jharkhand | E14: Ranchi | H14: Needs Verification | I14: Widely known state transport undertaking listed from general knowledge; no source retrieved yet. Name/HQ/website need verification.
A15: KSRTC-KA | B15: Karnataka State Road Transport Corporation | C15: State Transport | D15: Karnataka | E15: Bengaluru | H15: Needs Verification | I15: Widely known state transport undertaking listed from general knowledge; no source retrieved yet. Name/HQ/website need verification.
A16: BMTC | B16: Bangalore Metropolitan Transport Corporation | C16: State Transport | D16: Karnataka | E16: Bengaluru | H16: Needs Verification | I16: Widely known state transport undertaking listed from general knowledge; no source retrieved yet. Name/HQ/website need verification.
A17: KKRTC | B17: Kalyana Karnataka Road Transport Corporation | C17: State Transport | D17: Karnataka | E17: Kalaburagi | H17: Needs Verification | I17: Widely known state transport undertaking listed from general knowledge; no source retrieved yet. Name/HQ/website need verification.
A18: NWKRTC | B18: North Western Karnataka Road Transport Corporation | C18: State Transport | D18: Karnataka | E18: Hubballi | H18: Needs Verification | I18: Widely known state transport undertaking listed from general knowledge; no source retrieved yet. Name/HQ/website need verification.
A19: KSRTC-KL | B19: Kerala State Road Transport Corporation | C19: State Transport | D19: Kerala | E19: Thiruvananthapuram | H19: Needs Verification | I19: Widely known state transport undertaking listed from general knowledge; no source retrieved yet. Name/HQ/website need verification.
A20: MSRTC | B20: Maharashtra State Road Transport Corporation | C20: State Transport | D20: Maharashtra | E20: Mumbai | H20: Needs Verification | I20: Widely known state transport undertaking listed from general knowledge; no source retrieved yet. Name/HQ/website need verification.
... A39: PRTC-PY | B39: Puducherry Road Transport Corporation | C39: State Transport | D39: Puducherry | E39: Puducherry | H39: Needs Verification | I39: Widely known state transport undertaking listed from general knowledge; no source retrieved yet. Name/HQ/website need verification.

Sheet Sources
A1: Source_ID | B1: Source_Name | C1: Source_URL | D1: Source_Type | E1: Used_For | F1: Accessed | G1: Reliability_Note
A2: SRC-001 | B2: housing.com - 217 bus route Kolkata | C2: https://housing.com/news/217-bus-route-kolkata-narayanpur-to-babughat | D2: Secondary (property/news portal) | E2: WBTC route 217 Narayanpur-Babughat; Esplanade stop | F2: 46297 | G2: Not an official government/RTC source; use only as lead until confirmed on official site.
A3: SRC-002 | B3: housing.com - 205 bus route Kolkata | C3: https://housing.com/news/205-bus-route-in-kolkata-bansdroni-to-babughat | D3: Secondary (property/news portal) | E3: WBTC route 205 Bansdroni-Babughat | F3: 46297 | G3: Not an official government/RTC source; use only as lead until confirmed on official site.
A4: SRC-003 | B4: housing.com - AC12 bus route Kolkata | C4: https://housing.com/news/ac-12-bus-route-kolkata-shapoorji-to-howrah/ | D4: Secondary (property/news portal) | E4: WBTC AC12 Shapoorji-Howrah via Esplanade; points to wbtc.co.in | F4: 46297 | G4: Not an official government/RTC source; use only as lead until confirmed on official site.
A5: SRC-004 | B5: MakeMyTrip - WBTC Kolkata to Bolpur | C5: https://www.makemytrip.com/bus-tickets/wbtc-ctc-from-kolkata-to-bolpur-online-bus-tickets.html | D5: Aggregator (booking portal) | E5: Kolkata-Bolpur WBTC; Esplanade boarding point labels | F5: 46297 | G5: Not an official government/RTC source; use only as lead until confirmed on official site.
A6: SRC-005 | B6: MakeMyTrip - WBTC Kolkata to Durgapur | C6: https://www.makemytrip.com/bus-tickets/wbtc-ctc-from-kolkata-to-durgapur_west_bengal-online-bus-tickets.html | D6: Aggregator (booking portal) | E6: Kolkata-Durgapur/Asansol/Purulia SBSTC & WBTC listings; WBTC popular route list | F6: 46297 | G6: Not an official government/RTC source; use only as lead until confirmed on official site.
A7: SRC-006 | B7: MakeMyTrip - WBTC Kolkata to Arambagh | C7: https://www.makemytrip.com/bus-tickets/wbtc-ctc-from-kolkata-to-arambagh-online-bus-tickets.html | D7: Aggregator (booking portal) | E7: Kolkata-Arambagh SBSTC; Kolkata-Joyrambati-Bishnupur WBTC | F7: 46297 | G7: Not an official government/RTC source; use only as lead until confirmed on official site.
A8: SRC-007 | B8: MakeMyTrip - WBTC Kolkata to Purulia | C8: https://www.makemytrip.com/bus-tickets/wbtc-ctc-from-kolkata-to-purulia-online-bus-tickets.html | D8: Aggregator (booking portal) | E8: Kolkata-Purulia via Asansol/Bankura; AC Volvo Banglashree Express | F8: 46297 | G8: Not an official government/RTC source; use only as lead until confirmed on official site.
A9: SRC-008 | B9: Wikipedia - West Bengal Transport Corporation | C9: https://en.wikipedia.com/wiki/WBSTC | D9: Reference (Wikipedia) | E9: WBTC corporate background | F9: 46297 | G9: Not an official government/RTC source; use only as lead until confirmed on official site.
A10: SRC-009 | B10: Wikipedia - Bihar State Road Transport Corporation | C10: https://en.wikipedia.org/wiki/Bihar_State_Road_Transport_Corporation | D10: Reference (Wikipedia) | E10: BSRTC HQ/website; Pataliputra ISBT Patna; Volvo Patna/Kishanganj-Ghaziabad | F10: 46297 | G10: Not an official government/RTC source; use only as lead until confirmed on official site.
A11: SRC-010 | B11: Patna Press - BSRTC festive services | C11: https://patnapress.com/bsrtc-festive-season-bus-services/ | D11: News (regional) | E11: BSRTC festive buses to Anand Vihar; Kolkata-Patna timings | F11: 46297 | G11: Not an official government/RTC source; use only as lead until confirmed on official site.
A12: SRC-011 | B12: Patna Press - Bihar special festive buses | C12: https://patnapress.com/bihar-special-festive-buses/ | D12: News (regional) | E12: Kolkata-Bhagalpur BSRTC evening services | F12: 46297 | G12: Not an official government/RTC source; use only as lead until confirmed on official site.
A13: SRC-012 | B13: Patna Press - BSRTC 149 new deluxe buses | C13: https://patnapress.com/bihar-149-new-deluxe-buses-delhi-punjab-haryana-up-jharkhand/ | D13: News (regional) | E13: BSRTC interstate expansion (Delhi, Punjab, Haryana, UP, Jharkhand, WB) | F13: 46297 | G13: Not an official government/RTC source; use only as lead until confirmed on official site.
A14: SRC-013 | B14: Telegraph (My Kolkata) - Bus Terminus topic page | C14: https://obeta.ttef.in/topic/bus-terminus | D14: News topic index | E14: Headlines on Esplanade relocation, Santragachi terminus survey, Siliguri terminus revamp | F14: 46297 | G14: Not an official government/RTC source; use only as lead until confirmed on official site.

Sheet State_Summary
A1: State/UT | B1: Major_Cities_Count | C1: Terminal_Count | D1: Major_Terminal_Count | E1: Route_Count | F1: Interstate_Route_Count | G1: Operators_Count | H1: Data_Verification_Status | I1: Source_Count | J1: Last_Updated | K1: Region_Type
A2: West Bengal | B2: =COUNTIFS(Cities!$D$2:$D$380,$A2,Cities!$H$2:$H$380,"Y")+COUNTIFS(Cities!$E$2:$E$380,$A2,Cities!$H$2:$H$380,"Y") -> 6 | C2: =COUNTIF(Bus_Terminals!$F$2:$F$420,$A2)+COUNTIF(Bus_Terminals!$G$2:$G$420,$A2) -> 45 | D2: =COUNTIFS(Bus_Terminals!$F$2:$F$420,$A2,Bus_Terminals!$M$2:$M$420,"Y")+COUNTIFS(Bus_Terminals!$G$2:$G$420,$A2,Bus_Terminals!$M$2:$M$420,"Y") -> 9 | E2: =COUNTIF(Bus_Routes!$E$2:$E$18,$A2) -> 17 | F2: =COUNTIF(Interstate_Routes!$B$2:$B$10,$A2) -> 2 | G2: =COUNTIF(Bus_Operators!$D$2:$D$39,$A2) -> 3 | H2: =IF(C2=0,"No terminal records",IF(COUNTIFS(Bus_Terminals!$F$2:$F$420,$A2,Bus_Terminals!$U$2:$U$420,"Partially Verified")+COUNTIFS(Bus_Terminals!$G$2:$G$420,$A2,Bus_Terminals!$U$2:$U$420,"Partially Verified")>0,"Partial - some records sourced","Candidate only - needs verification")) -> Partial - some records sourced | I2: =COUNTIFS(Bus_Terminals!$F$2:$F$420,$A2,Bus_Terminals!$S$2:$S$420,"<>")+COUNTIFS(Bus_Terminals!$G$2:$G$420,$A2,Bus_Terminals!$S$2:$S$420,"<>") -> 9 | J2: 46297 | K2: State
A3: Andhra Pradesh | B3: =COUNTIFS(Cities!$D$2:$D$380,$A3,Cities!$H$2:$H$380,"Y")+COUNTIFS(Cities!$E$2:$E$380,$A3,Cities!$H$2:$H$380,"Y") -> 4 | C3: =COUNTIF(Bus_Terminals!$F$2:$F$420,$A3)+COUNTIF(Bus_Terminals!$G$2:$G$420,$A3) -> 14 | D3: =COUNTIFS(Bus_Terminals!$F$2:$F$420,$A3,Bus_Terminals!$M$2:$M$420,"Y")+COUNTIFS(Bus_Terminals!$G$2:$G$420,$A3,Bus_Terminals!$M$2:$M$420,"Y") -> 4 | E3: =COUNTIF(Bus_Routes!$E$2:$E$18,$A3) -> 0 | F3: =COUNTIF(Interstate_Routes!$B$2:$B$10,$A3) -> 0 | G3: =COUNTIF(Bus_Operators!$D$2:$D$39,$A3) -> 1 | H3: =IF(C3=0,"No terminal records",IF(COUNTIFS(Bus_Terminals!$F$2:$F$420,$A3,Bus_Terminals!$U$2:$U$420,"Partially Verified")+COUNTIFS(Bus_Terminals!$G$2:$G$420,$A3,Bus_Terminals!$U$2:$U$420,"Partially Verified")>0,"Partial - some records sourced","Candidate only - needs verification")) -> Candidate only - needs verification | I3: =COUNTIFS(Bus_Terminals!$F$2:$F$420,$A3,Bus_Terminals!$S$2:$S$420,"<>")+COUNTIFS(Bus_Terminals!$G$2:$G$420,$A3,Bus_Terminals!$S$2:$S$420,"<>") -> 0 | J3: 46297 | K3: State
A4: Arunachal Pradesh | B4: =COUNTIFS(Cities!$D$2:$D$380,$A4,Cities!$H$2:$H$380,"Y")+COUNTIFS(Cities!$E$2:$E$380,$A4,Cities!$H$2:$H$380,"Y") -> 1 | C4: =COUNTIF(Bus_Terminals!$F$2:$F$420,$A4)+COUNTIF(Bus_Terminals!$G$2:$G$420,$A4) -> 8 | D4: =COUNTIFS(Bus_Terminals!$F$2:$F$420,$A4,Bus_Terminals!$M$2:$M$420,"Y")+COUNTIFS(Bus_Terminals!$G$2:$G$420,$A4,Bus_Terminals!$M$2:$M$420,"Y") -> 1 | E4: =COUNTIF(Bus_Routes!$E$2:$E$18,$A4) -> 0 | F4: =COUNTIF(Interstate_Routes!$B$2:$B$10,$A4) -> 0 | G4: =COUNTIF(Bus_Operators!$D$2:$D$39,$A4) -> 1 | H4: =IF(C4=0,"No terminal records",IF(COUNTIFS(Bus_Terminals!$F$2:$F$420,$A4,Bus_Terminals!$U$2:$U$420,"Partially Verified")+COUNTIFS(Bus_Terminals!$G$2:$G$420,$A4,Bus_Terminals!$U$2:$U$420,"Partially Verified")>0,"Partial - some records sourced","Candidate only - needs verification")) -> Candidate only - needs verification | I4: =COUNTIFS(Bus_Terminals!$F$2:$F$420,$A4,Bus_Terminals!$S$2:$S$420,"<>")+COUNTIFS(Bus_Terminals!$G$2:$G$420,$A4,Bus_Terminals!$S$2:$S$420,"<>") -> 0 | J4: 46297 | K4: State
A5: Assam | B5: =COUNTIFS(Cities!$D$2:$D$380,$A5,Cities!$H$2:$H$380,"Y")+COUNTIFS(Cities!$E$2:$E$380,$A5,Cities!$H$2:$H$380,"Y") -> 1 | C5: =COUNTIF(Bus_Terminals!$F$2:$F$420,$A5)+COUNTIF(Bus_Terminals!$G$2:$G$420,$A5) -> 14 | D5: =COUNTIFS(Bus_Terminals!$F$2:$F$420,$A5,Bus_Terminals!$M$2:$M$420,"Y")+COUNTIFS(Bus_Terminals!$G$2:$G$420,$A5,Bus_Terminals!$M$2:$M$420,"Y") -> 2 | E5: =COUNTIF(Bus_Routes!$E$2:$E$18,$A5) -> 0 | F5: =COUNTIF(Interstate_Routes!$B$2:$B$10,$A5) -> 0 | G5: =COUNTIF(Bus_Operators!$D$2:$D$39,$A5) -> 1 | H5: =IF(C5=0,"No terminal records",IF(COUNTIFS(Bus_Terminals!$F$2:$F$420,$A5,Bus_Terminals!$U$2:$U$420,"Partially Verified")+COUNTIFS(Bus_Terminals!$G$2:$G$420,$A5,Bus_Terminals!$U$2:$U$420,"Partially Verified")>0,"Partial - some records sourced","Candidate only - needs verification")) -> Candidate only - needs verification | I5: =COUNTIFS(Bus_Terminals!$F$2:$F$420,$A5,Bus_Terminals!$S$2:$S$420,"<>")+COUNTIFS(Bus_Terminals!$G$2:$G$420,$A5,Bus_Terminals!$S$2:$S$420,"<>") -> 0 | J5: 46297 | K5: State
A6: Bihar | B6: =COUNTIFS(Cities!$D$2:$D$380,$A6,Cities!$H$2:$H$380,"Y")+COUNTIFS(Cities!$E$2:$E$380,$A6,Cities!$H$2:$H$380,"Y") -> 1 | C6: =COUNTIF(Bus_Terminals!$F$2:$F$420,$A6)+COUNTIF(Bus_Terminals!$G$2:$G$420,$A6) -> 19 | D6: =COUNTIFS(Bus_Terminals!$F$2:$F$420,$A6,Bus_Terminals!$M$2:$M$420,"Y")+COUNTIFS(Bus_Terminals!$G$2:$G$420,$A6,Bus_Terminals!$M$2:$M$420,"Y") -> 5 | E6: =COUNTIF(Bus_Routes!$E$2:$E$18,$A6) -> 0 | F6: =COUNTIF(Interstate_Routes!$B$2:$B$10,$A6) -> 7 | G6: =COUNTIF(Bus_Operators!$D$2:$D$39,$A6) -> 1 | H6: =IF(C6=0,"No terminal records",IF(COUNTIFS(Bus_Terminals!$F$2:$F$420,$A6,Bus_Terminals!$U$2:$U$420,"Partially Verified")+COUNTIFS(Bus_Terminals!$G$2:$G$420,$A6,Bus_Terminals!$U$2:$U$420,"Partially Verified")>0,"Partial - some records sourced","Candidate only - needs verification")) -> Partial - some records sourced | I6: =COUNTIFS(Bus_Terminals!$F$2:$F$420,$A6,Bus_Terminals!$S$2:$S$420,"<>")+COUNTIFS(Bus_Terminals!$G$2:$G$420,$A6,Bus_Terminals!$S$2:$S$420,"<>") -> 1 | J6: 46297 | K6: State
A7: Chhattisgarh | B7: =COUNTIFS(Cities!$D$2:$D$380,$A7,Cities!$H$2:$H$380,"Y")+COUNTIFS(Cities!$E$2:$E$380,$A7,Cities!$H$2:$H$380,"Y") -> 2 | C7: =COUNTIF(Bus_Terminals!$F$2:$F$420,$A7)+COUNTIF(Bus_Terminals!$G$2:$G$420,$A7) -> 10 | D7: =COUNTIFS(Bus_Terminals!$F$2:$F$420,$A7,Bus_Terminals!$M$2:$M$420,"Y")+COUNTIFS(Bus_Terminals!$G$2:$G$420,$A7,Bus_Terminals!$M$2:$M$420,"Y") -> 2 | E7: =COUNTIF(Bus_Routes!$E$2:$E$18,$A7) -> 0 | F7: =COUNTIF(Interstate_Routes!$B$2:$B$10,$A7) -> 0 | G7: =COUNTIF(Bus_Operators!$D$2:$D$39,$A7) -> 1 | H7: =IF(C7=0,"No terminal records",IF(COUNTIFS(Bus_Terminals!$F$2:$F$420,$A7,Bus_Terminals!$U$2:$U$420,"Partially Verified")+COUNTIFS(Bus_Terminals!$G$2:$G$420,$A7,Bus_Terminals!$U$2:$U$420,"Partially Verified")>0,"Partial - some records sourced","Candidate only - needs verification")) -> Candidate only - needs verification | I7: =COUNTIFS(Bus_Terminals!$F$2:$F$420,$A7,Bus_Terminals!$S$2:$S$420,"<>")+COUNTIFS(Bus_Terminals!$G$2:$G$420,$A7,Bus_Terminals!$S$2:$S$420,"<>") -> 0 | J7: 46297 | K7: State
